Workbook

Sheet SV com Ptax
A1: Asset | B1: Último | C1: Abertura | D1: Máximo | E1: Mínimo | F1: Fechamento Anterior | G1: Variação (%) | I1: Contrato Atual | J1: Vencimento | K1: Dias úteis | L1: Dia | M1: Vencimento2 | N1: Dias úteis
A2: DI1FUT | B2: =RTD("rtdtrading.rtdserver",, "DI1FUT_F_0", "ULT") -> 0 | C2: =RTD("rtdtrading.rtdserver",, "DI1FUT_F_0", "ABE") -> 0 | D2: =RTD("rtdtrading.rtdserver",, "DI1FUT_F_0", "MAX") -> 0 | E2: =RTD("rtdtrading.rtdserver",, "DI1FUT_F_0", "MIN") -> 0 | F2: =RTD("rtdtrading.rtdserver",, "DI1FUT_F_0", "FEC") -> 0 | G2: =RTD("rtdtrading.rtdserver",, "DI1FUT_F_0", "VAR") -> 0 | I2: WDOZ25 | J2: 46023 | K2: =NETWORKDAYS(TODAY(), J2)-1 -> -175 | L2: 45944 | M2: 45962 | N2: =NETWORKDAYS(L2,Tabela4[[#This Row],[Vencimento2]])-1 -> 13
A3: DOLFUT | B3: =RTD("rtdtrading.rtdserver",, "DOLFUT_F_0", "ULT") -> 0 | C3: =RTD("rtdtrading.rtdserver",, "DOLFUT_F_0", "ABE") -> 0 | D3: =RTD("rtdtrading.rtdserver",, "DOLFUT_F_0", "MAX") -> 0 | E3: =RTD("rtdtrading.rtdserver",, "DOLFUT_F_0", "MIN") -> 0 | F3: =RTD("rtdtrading.rtdserver",, "DOLFUT_F_0", "FEC") -> 0 | G3: =RTD("rtdtrading.rtdserver",, "DOLFUT_F_0", "VAR") -> 0
A4: WDOFUT | B4: =RTD("rtdtrading.rtdserver",, "WDOFUT_F_0", "ULT") -> 0 | C4: =RTD("rtdtrading.rtdserver",, "WDOFUT_F_0", "ABE") -> 0 | D4: =RTD("rtdtrading.rtdserver",, "WDOFUT_F_0", "MAX") -> 0 | E4: =RTD("rtdtrading.rtdserver",, "WDOFUT_F_0", "MIN") -> 0 | F4: =RTD("rtdtrading.rtdserver",, "WDOFUT_F_0", "FEC") -> 0 | G4: =RTD("rtdtrading.rtdserver",, "WDOFUT_F_0", "VAR") -> 0
A5: FRP0 | B5: =RTD("rtdtrading.rtdserver",, "FRP0_F_0", "ULT") -> 0 | C5: =RTD("rtdtrading.rtdserver",, "FRP0_F_0", "ABE") -> 0 | D5: =RTD("rtdtrading.rtdserver",, "FRP0_F_0", "MAX") -> 0 | E5: =RTD("rtdtrading.rtdserver",, "FRP0_F_0", "MIN") -> 0 | F5: =RTD("rtdtrading.rtdserver",, "FRP0_F_0", "FEC") -> 0 | G5: =RTD("rtdtrading.rtdserver",, "FRP0_F_0", "VAR") -> 0
A6: FRP0 1º negócio | B6: =C5 -> 0
E7: Diferença | F7: =IF(E9=0,0,(1-$F$4/G12)) -> 1 | I7: Diferença | J7: =IF(I9=0,0,(1-$F$4/K12)) -> 1
A8: DX | B8: Pontos | C8: 27 | E8: Ptax Spot 1 | F8: Pontos | G8: 27 | I8: Ptax Spot 2 | J8: Pontos | K8: 27
A9: -0.0016 | B9: 3 DP | C9: =C10+24 -> 74.9984 | E9: ='SV com Ptax'!B31 -> 5181.4 | F9: 3 DP | G9: =G10+24 -> 5256.4 | I9: =('SV com Ptax'!B32) -> 5181 | J9: 3 DP | K9: =K10+24 -> 5256.2
B10: 2 DP | C10: =C11+24 -> 50.9984 | E10: + | F10: 2 DP | G10: =G11+24 -> 5232.4 | I10: + | J10: 2 DP | K10: =K11+24 -> 5232.2
B11: 1 DP | C11: =C12+C8 -> 26.9984 | E11: FRP0 | F11: 1 DP | G11: =G12+G8 -> 5208.4 | I11: FRP0 | J11: 1 DP | K11: =K12+K8 -> 5208.2
B12: Equilíbrio | C12: =F4+(A9) -> -0.0016 | E12: =B6 -> 0 | F12: Equilíbrio | G12: =E15 -> 5181.4 | I12: =E12 -> 0 | J12: Equilíbrio | K12: =(I15+E15)/2 -> 5181.2
B13: 1 DP | C13: 5572.77 | E13: = | F13: 1 DP | G13: =G12-G8 -> 5154.4 | I13: = | J13: 1 DP | K13: =K12-K8 -> 5154.2
B14: 2 DP | C14: =C13-24 -> 5548.77 | E14: Ptax Futuro | F14: 2 DP | G14: =G13-24 -> 5130.4 | I14: Ptax Futuro | J14: 2 DP | K14: =K13-24 -> 5130.2
B15: 3 DP | C15: =C14-24 -> 5524.77 | E15: =E9+E12 -> 5181.4 | F15: 3 DP | G15: =G14-24 -> 5106.4 | I15: =I9+I12 -> 5181 | J15: 3 DP | K15: =K14-24 -> 5106.2
A17: Diferença | B17: =IF(A19=0,0,(1-$F$4/C22)) -> 1 | E17: Diferença | F17: =IF(E19=0,0,(1-$F$4/G22)) -> 1 | I17: Diferença | J17: =IF(I19=0,0,(1-$F$4/K22)) -> 1
A18: Ptax Spot 3 | B18: Pontos | C18: 27 | E18: Ptax Spot 4 | F18: Pontos | G18: 27 | I18: Ptax Final | J18: Pontos | K18: 27
A19: =('SV com Ptax'!B33+'SV com Ptax'!B32)/2 -> 5182 | B19: 3 DP | C19: =C20+24 -> 5256.4667 | E19: =('SV com Ptax'!B34+'SV com Ptax'!B33)/2 -> 5182.05 | F19: 3 DP | G19: =G20+24 -> 5256.6125 | I19: ='SV com Ptax'!B35 -> 5181.62 | J19: 3 DP | K19: =K20+24 -> 5256.614
A20: + | B20: 2 DP | C20: =C21+24 -> 5232.4667 | E20: + | F20: 2 DP | G20: =G21+24 -> 5232.6125 | I20: + | J20: 2 DP | K20: =K21+24 -> 5232.614
A21: FRP0 | B21: 1 DP | C21: =C22+C18 -> 5208.4667 | E21: FRP0 | F21: 1 DP | G21: =G22+G18 -> 5208.6125 | I21: FRP0 | J21: 1 DP | K21: =K22+K18 -> 5208.614
A22: =E12 -> 0 | B22: Equilíbrio | C22: =(A25+I15+E15)/3 -> 5181.4667 | E22: =E12 -> 0 | F22: Equilíbrio | G22: =(E25+A25+I15+E15)/4 -> 5181.6125 | I22: =I12 -> 0 | J22: Equilíbrio | K22: =(I25+E25+A25+I15+E15)/5 -> 5181.614
A23: = | B23: 1 DP | C23: =C22-C18 -> 5154.4667 | E23: = | F23: 1 DP | G23: =G22-G18 -> 5154.6125 | I23: = | J23: 1 DP | K23: =K22-K18 -> 5154.614
A24: Ptax Futuro | B24: 2 DP | C24: =C23-24 -> 5130.4667 | E24: Ptax Futuro | F24: 2 DP | G24: =G23-24 -> 5130.6125 | I24: Ptax Futuro | J24: 2 DP | K24: =K23-24 -> 5130.614
A25: =A19+A22 -> 5182 | B25: 3 DP | C25: =C24-24 -> 5106.4667 | E25: =E19+E22 -> 5182.05 | F25: 3 DP | G25: =G24-24 -> 5106.6125 | I25: =I19+I22 -> 5181.62 | J25: 3 DP | K25: =K24-24 -> 5106.614
B28: Atualizar Diariamente somente DX
A30: DATA | B30: 46265
A31: PTAX 1 | B31: {=IFERROR(_xlfn.LET(_xlpm.d,$B$30, _xlpm.linhas, _xlfn._xlws.FILTER(VALUE(Tabela1[Column1.dataHoraCotacao]), INT(VALUE(Tabela1[Column1.dataHoraCotacao]))=_xlpm.d), _xlpm.valores, _xlfn._xlws.FILTER(Tabela1[Column1.cotacaoVenda], INT(VALUE(Tabela1[Column1.dataHoraCotacao]))=_xlpm.d), IFERROR( INDEX(_xlpm.valores, MATCH(SMALL(_xlpm.linhas,1), _xlpm.linhas,0)), "—"))*1000,0)} -> 5181.4
A32: PTAX 2 | B32: {=IFERROR(_xlfn.LET(_xlpm.d,$B$30, _xlpm.linhas, _xlfn._xlws.FILTER(VALUE(Tabela1[Column1.dataHoraCotacao]), INT(VALUE(Tabela1[Column1.dataHoraCotacao]))=_xlpm.d), _xlpm.valores, _xlfn._xlws.FILTER(Tabela1[Column1.cotacaoVenda], INT(VALUE(Tabela1[Column1.dataHoraCotacao]))=_xlpm.d), IFERROR( INDEX(_xlpm.valores, MATCH(SMALL(_xlpm.linhas,2), _xlpm.linhas,0)), "—"))*1000,0)} -> 5181
A33: PTAX 3 | B33: {=IFERROR(_xlfn.LET(_xlpm.d,$B$30, _xlpm.linhas, _xlfn._xlws.FILTER(VALUE(Tabela1[Column1.dataHoraCotacao]), INT(VALUE(Tabela1[Column1.dataHoraCotacao]))=_xlpm.d), _xlpm.valores, _xlfn._xlws.FILTER(Tabela1[Column1.cotacaoVenda], INT(VALUE(Tabela1[Column1.dataHoraCotacao]))=_xlpm.d), IFERROR( INDEX(_xlpm.valores, MATCH(SMALL(_xlpm.linhas,3), _xlpm.linhas,0)), "—"))*1000,0)} -> 5183
A34: PTAX 4 | B34: {=IFERROR(_xlfn.LET(_xlpm.d,$B$30, _xlpm.linhas, _xlfn._xlws.FILTER(VALUE(Tabela1[Column1.dataHoraCotacao]), INT(VALUE(Tabela1[Column1.dataHoraCotacao]))=_xlpm.d), _xlpm.valores, _xlfn._xlws.FILTER(Tabela1[Column1.cotacaoVenda], INT(VALUE(Tabela1[Column1.dataHoraCotacao]))=_xlpm.d), IFERROR( INDEX(_xlpm.valores, MATCH(SMALL(_xlpm.linhas,4), _xlpm.linhas,0)), "—"))*1000,0)} -> 5181.1
A35: PTAX FINAL | B35: {=IFERROR(_xlfn.LET(_xlpm.d,$B$30, _xlpm.valores, _xlfn._xlws.FILTER(Tabela1[Column1.cotacaoVenda], INT(VALUE(Tabela1[Column1.dataHoraCotacao]))=_xlpm.d), IFERROR(AVERAGE(_xlpm.valores), "—"))*1000,0)} -> 5181.62

Sheet DADOS HISTÓRICOS
A1: DIA | B1: DX | C1: D1FUT_D-1 | E1: Horário | F1: Média Vol DOLFUT | G1: DesvPad de Vol DOLFUT | I1: Volume Acumulado | L1: Horário | M1: Média Vol DOLFUT | N1: DesvPad de Vol DOLFUT
A2: 45902 | C2: 13.223 | E2: 0.375 | F2: 4.3519261e+09 | G2: 2.1208294e+09 | I2: =GETPIVOTDATA("Média Vol DOLFUT",$E$1,"Hora",E2) -> 4.3519261e+09 | L2: jan | M2: 3.5164597e+09 | N2: 2.1141396e+09
A3: 45903 | C3: 13.284 | E3: 0.39583333 | F3: 4.6621096e+09 | G3: 2.0842781e+09 | I3: =I2+GETPIVOTDATA("Média Vol DOLFUT",$E$1,"Hora",E3) -> 9.0140357e+09 | L3: fev | M3: 3.7204707e+09 | N3: 2.0829996e+09
A4: 45904 | C4: 13.294 | E4: 0.41666667 | F4: 5.3745333e+09 | G4: 2.1626577e+09 | I4: =I3+GETPIVOTDATA("Média Vol DOLFUT",$E$1,"Hora",E4) -> 1.4388569e+10 | L4: mar | M4: 4.1750936e+09 | N4: 2.399249e+09
A5: 45905 | C5: 13.28 | E5: 0.4375 | F5: 5.2913171e+09 | G5: 2.2330767e+09 | I5: =I4+GETPIVOTDATA("Média Vol DOLFUT",$E$1,"Hora",E5) -> 1.9679886e+10 | L5: abr | M5: 3.9002843e+09 | N5: 2.6497764e+09
A6: 45908 | C6: 13.223 | E6: 0.45833333 | F6: 5.4991731e+09 | G6: 2.3604644e+09 | I6: =I5+GETPIVOTDATA("Média Vol DOLFUT",$E$1,"Hora",E6) -> 2.5179059e+10 | L6: mai | M6: 3.2257455e+09 | N6: 2.025224e+09
A7: 45909 | C7: 13.246 | E7: 0.47916667 | F7: 4.821581e+09 | G7: 2.0879254e+09 | I7: =I6+GETPIVOTDATA("Média Vol DOLFUT",$E$1,"Hora",E7) -> 3.000064e+10 | L7: jun | M7: 3.4605088e+09 | N7: 2.051864e+09
A8: 45910 | B8: 0.0003 | C8: 13.27 | E8: 0.5 | F8: 4.7399967e+09 | G8: 2.3445327e+09 | I8: =I7+GETPIVOTDATA("Média Vol DOLFUT",$E$1,"Hora",E8) -> 3.4740637e+10 | L8: Total Geral | M8: 3.6895052e+09 | N8: 2.2754082e+09
A9: 45911 | B9: -0.0017 | C9: 13.303 | E9: 0.52083333 | F9: 3.5873279e+09 | G9: 2.0440172e+09 | I9: =I8+GETPIVOTDATA("Média Vol DOLFUT",$E$1,"Hora",E9) -> 3.8327965e+10
A10: 45912 | B10: 0.0019 | C10: 13.327 | E10: 0.54166667 | F10: 3.6816829e+09 | G10: 1.982517e+09 | I10: =I9+GETPIVOTDATA("Média Vol DOLFUT",$E$1,"Hora",E10) -> 4.2009647e+10
A11: 45915 | B11: -0.0018 | C11: 13.322 | E11: 0.5625 | F11: 3.0011884e+09 | G11: 1.7285224e+09 | I11: =I10+GETPIVOTDATA("Média Vol DOLFUT",$E$1,"Hora",E11) -> 4.5010836e+10
A12: 45916 | B12: -0.0035 | C12: 13.294 | E12: 0.58333333 | F12: 3.1348042e+09 | G12: 1.8743466e+09 | I12: =I11+GETPIVOTDATA("Média Vol DOLFUT",$E$1,"Hora",E12) -> 4.814564e+10
A13: 45917 | B13: 0.0017 | C13: 13.251 | E13: 0.60416667 | F13: 3.4312925e+09 | G13: 1.9099993e+09 | I13: =I12+GETPIVOTDATA("Média Vol DOLFUT",$E$1,"Hora",E13) -> 5.1576933e+10
A14: 45918 | B14: 0.002 | C14: 13.242 | E14: 0.625 | F14: 3.8523883e+09 | G14: 1.9611774e+09 | I14: =I13+GETPIVOTDATA("Média Vol DOLFUT",$E$1,"Hora",E14) -> 5.5429321e+10
A15: 45919 | B15: 0.004 | C15: 13.294 | E15: 0.64583333 | F15: 3.7908704e+09 | G15: 1.9547376e+09 | I15: =I14+GETPIVOTDATA("Média Vol DOLFUT",$E$1,"Hora",E15) -> 5.9220191e+10
A16: 45922 | B16: -0.0017 | C16: 13.299 | E16: 0.66666667 | F16: 3.09936e+09 | G16: 1.5013622e+09 | I16: =I15+GETPIVOTDATA("Média Vol DOLFUT",$E$1,"Hora",E16) -> 6.2319551e+10
A17: 45923 | B17: -0.0002 | C17: 14.05 | E17: 0.6875 | F17: 2.6874754e+09 | G17: 1.8784086e+09 | I17: =I16+GETPIVOTDATA("Média Vol DOLFUT",$E$1,"Hora",E17) -> 6.5007027e+10
A18: 45924 | B18: 0.0048 | C18: 13.99 | E18: 0.70833333 | F18: 2.4538794e+09 | G18: 1.8304002e+09 | I18: =I17+GETPIVOTDATA("Média Vol DOLFUT",$E$1,"Hora",E18) -> 6.7460906e+10
A19: 45925 | B19: 0.0001 | C19: 14.01 | E19: 0.72916667 | F19: 1.6740643e+09 | G19: 1.2291389e+09 | I19: =I18+GETPIVOTDATA("Média Vol DOLFUT",$E$1,"Hora",E19) -> 6.913497e+10
A20: 45926 | B20: -0.0011 | C20: 13.365 | E20: 0.75 | F20: 9.81255e+08 | G20: 7.9721027e+08 | I20: =I19+GETPIVOTDATA("Média Vol DOLFUT",$E$1,"Hora",E20) -> 7.0116225e+10
A21: 45929 | B21: -0.0022 | C21: 13.315 | E21: Total Geral | F21: 3.6895052e+09 | G21: 2.2754082e+09
A22: 45930 | B22: -0.0008 | C22: 13.385
A23: 45931 | B23: -0.0006 | C23: 13.38
A24: 45932 | B24: -0.0007 | C24: 13.375
A25: 45933 | C25: 13.465
A26: 45936 | B26: 0.0058 | C26: 13.525
A27: 45937 | B27: 0.004 | C27: 13.48
A28: 45938 | B28: 0.0025 | C28: 13.535
A29: 45939 | B29: 0.0007 | C29: 13.475
A30: 45940 | B30: -0.0015 | C30: 13.395
A31: 45943 | B31: 0.0026 | C31: 13.43
A32: 45944 | B32: 0.0015 | C32: 13.43
A33: 45945 | B33: -0.0017 | C33: 13.385
A34: 45946 | B34: -0.0016 | C34: 13.375
A35: 45947
A36: 45950 | B36: 0.0012 | C36: 13.36
A37: 45951 | B37: 0.0026 | C37: 13.265
A38: 45952 | B38: 0.0015 | C38: 13.23
A39: 45953 | B39: 0.0025 | C39: 13.145
A40: 45954 | B40: 0.0012 | C40: 13.12
...

Sheet 01_07 a 10_10 DOLFUT VOL 30min
A1: Ativo | B1: Data | C1: Hora | D1: Abertura | E1: Máximo | F1: Mínimo | G1: Fechamento | H1: Volume | I1: Quantidade
A2: DOLFUT | B2: 46181 | C2: 0.60416667 | D2: 5216.5 | E2: 5221.5 | F2: 5215.5 | G2: 5217.5 | H2: 2678648000 | I2: 10265
A3: DOLFUT | B3: 46181 | C3: 0.58333333 | D3: 5205.5 | E3: 5219 | F3: 5205 | G3: 5216 | H3: 4183870125 | I3: 16055
A4: DOLFUT | B4: 46181 | C4: 0.5625 | D4: 5199 | E4: 5205.5 | F4: 5197 | G4: 5205 | H4: 2720294750 | I4: 10460
A5: DOLFUT | B5: 46181 | C5: 0.54166667 | D5: 5199 | E5: 5202.5 | F5: 5191.5 | G5: 5199 | H5: 2424041125 | I5: 9330
A6: DOLFUT | B6: 46181 | C6: 0.52083333 | D6: 5205 | E6: 5215 | F6: 5198 | G6: 5199 | H6: 3661912250 | I6: 14070
A7: DOLFUT | B7: 46181 | C7: 0.5 | D7: 5204 | E7: 5211.5 | F7: 5196 | G7: 5205.5 | H7: 3542477125 | I7: 13615
A8: DOLFUT | B8: 46181 | C8: 0.47916667 | D8: 5215 | E8: 5217 | F8: 5203 | G8: 5204.5 | H8: 6015507250 | I8: 23095
A9: DOLFUT | B9: 46181 | C9: 0.45833333 | D9: 5205 | E9: 5224.5 | F9: 5199.5 | G9: 5215.5 | H9: 6039318625 | I9: 23160
A10: DOLFUT | B10: 46181 | C10: 0.4375 | D10: 5189 | E10: 5204.5 | F10: 5183.5 | G10: 5204.5 | H10: 5261431125 | I10: 20260
A11: DOLFUT | B11: 46181 | C11: 0.41666667 | D11: 5179 | E11: 5196.5 | F11: 5176 | G11: 5188.5 | H11: 12031361380 | I11: 46405
A12: DOLFUT | B12: 46181 | C12: 0.39583333 | D12: 5165 | E12: 5195.5 | F12: 5163 | G12: 5179.5 | H12: 7019816750 | I12: 27120
A13: DOLFUT | B13: 46181 | C13: 0.375 | D13: 5180.5 | E13: 5185 | F13: 5162.5 | G13: 5165 | H13: 4157310625 | I13: 16070
... A4078: DOLFUT | B4078: 45659 | C4078: 0.375 | D4078: 6647.828 | E4078: 6686.354 | F4078: 6637.661 | G4078: 6686.354 | H4078: 6.5719325e+09 | I4078: 19720

Sheet PTAX BC
A1: Column1.cotacaoVenda | B1: Column1.dataHoraCotacao
A2: 5.1833 | B2: 46266.42
A3: 5.1816 | B3: 46265.548
A4: 5.1811 | B4: 46265.548
A5: 5.183 | B5: 46265.508
A6: 5.181 | B6: 46265.463
A7: 5.1814 | B7: 46265.424
A8: 5.2005 | B8: 46262.55
A9: 5.2255 | B9: 46262.55
A10: 5.2087 | B10: 46262.506
A11: 5.1921 | B11: 46262.463
A12: 5.1758 | B12: 46262.424
A13: 5.1642 | B13: 46261.549
... A2059: 6.1084 | B2059: 45666.42

Sheet RTD
A1: Asset | B1: Data | C1: Hora | D1: Último | E1: Abertura | F1: Máximo | G1: Mínimo | H1: Fechamento Anterior | I1: Variação | J1: Ajuste | K1: Aj. Anterior | L1: Vencimento | M1: RGM_AJUSTE_D0_DOL
A2: DAPFUT | B2: =RTD("rtdtrading.rtdserver",, "DAPFUT_F_0", "DAT") -> 30/12/1899 | C2: =RTD("rtdtrading.rtdserver",, "DAPFUT_F_0", "HOR") -> 00:00:00 | D2: =RTD("rtdtrading.rtdserver",, "DAPFUT_F_0", "ULT") -> 0 | E2: =RTD("rtdtrading.rtdserver",, "DAPFUT_F_0", "ABE") -> 0 | F2: =RTD("rtdtrading.rtdserver",, "DAPFUT_F_0", "MAX") -> 0 | G2: =RTD("rtdtrading.rtdserver",, "DAPFUT_F_0", "MIN") -> 0 | H2: =RTD("rtdtrading.rtdserver",, "DAPFUT_F_0", "FEC") -> 0 | I2: =RTD("rtdtrading.rtdserver",, "DAPFUT_F_0", "VAR") -> 0 | J2: =RTD("rtdtrading.rtdserver",, "DAPFUT_F_0", "AJU") -> 0 | K2: =RTD("rtdtrading.rtdserver",, "DAPFUT_F_0", "AJA") -> 0 | L2: =RTD("rtdtrading.rtdserver",, "DAPFUT_F_0", "VEN") -> 11/09/2026 | M2: =RTD("rtdtrading.rtdserver",, "DAPFUT_F_0", "101_RGM_AJUSTE_D0_DOL")
A3: DI1FUT | B3: =RTD("rtdtrading.rtdserver",, "DI1FUT_F_0", "DAT") -> 30/12/1899 | C3: =RTD("rtdtrading.rtdserver",, "DI1FUT_F_0", "HOR") -> 00:00:00 | D3: =RTD("rtdtrading.rtdserver",, "DI1FUT_F_0", "ULT") -> 0 | E3: =RTD("rtdtrading.rtdserver",, "DI1FUT_F_0", "ABE") -> 0 | F3: =RTD("rtdtrading.rtdserver",, "DI1FUT_F_0", "MAX") -> 0 | G3: =RTD("rtdtrading.rtdserver",, "DI1FUT_F_0", "MIN") -> 0 | H3: =RTD("rtdtrading.rtdserver",, "DI1FUT_F_0", "FEC") -> 0 | I3: =RTD("rtdtrading.rtdserver",, "DI1FUT_F_0", "VAR") -> 0 | J3: =RTD("rtdtrading.rtdserver",, "DI1FUT_F_0", "AJU") -> 0 | K3: =RTD("rtdtrading.rtdserver",, "DI1FUT_F_0", "AJA") -> 0 | L3: =RTD("rtdtrading.rtdserver",, "DI1FUT_F_0", "VEN") -> 11/09/2026 | M3: =RTD("rtdtrading.rtdserver",, "DI1FUT_F_0", "101_RGM_AJUSTE_D0_DOL")
A4: DX1FUT | B4: =RTD("rtdtrading.rtdserver",, "DX1FUT_F_0", "DAT") -> 30/12/1899 | C4: =RTD("rtdtrading.rtdserver",, "DX1FUT_F_0", "HOR") -> 00:00:00 | D4: =RTD("rtdtrading.rtdserver",, "DX1FUT_F_0", "ULT") -> 0 | E4: =RTD("rtdtrading.rtdserver",, "DX1FUT_F_0", "ABE") -> 0 | F4: =RTD("rtdtrading.rtdserver",, "DX1FUT_F_0", "MAX") -> 0 | G4: =RTD("rtdtrading.rtdserver",, "DX1FUT_F_0", "MIN") -> 0 | H4: =RTD("rtdtrading.rtdserver",, "DX1FUT_F_0", "FEC") -> 0 | I4: =RTD("rtdtrading.rtdserver",, "DX1FUT_F_0", "VAR") -> 0 | J4: =RTD("rtdtrading.rtdserver",, "DX1FUT_F_0", "AJU") -> 0 | K4: =RTD("rtdtrading.rtdserver",, "DX1FUT_F_0", "AJA") -> 0 | L4: =RTD("rtdtrading.rtdserver",, "DX1FUT_F_0", "VEN") -> 11/09/2026 | M4: =RTD("rtdtrading.rtdserver",, "DX1FUT_F_0", "101_RGM_AJUSTE_D0_DOL")
A5: FRP0 | B5: =RTD("rtdtrading.rtdserver",, "FRP0_F_0", "DAT") -> 30/12/1899 | C5: =RTD("rtdtrading.rtdserver",, "FRP0_F_0", "HOR") -> 00:00:00 | D5: =RTD("rtdtrading.rtdserver",, "FRP0_F_0", "ULT") -> 0 | E5: =RTD("rtdtrading.rtdserver",, "FRP0_F_0", "ABE") -> 0 | F5: =RTD("rtdtrading.rtdserver",, "FRP0_F_0", "MAX") -> 0 | G5: =RTD("rtdtrading.rtdserver",, "FRP0_F_0", "MIN") -> 0 | H5: =RTD("rtdtrading.rtdserver",, "FRP0_F_0", "FEC") -> 0 | I5: =RTD("rtdtrading.rtdserver",, "FRP0_F_0", "VAR") -> 0 | J5: =RTD("rtdtrading.rtdserver",, "FRP0_F_0", "AJU") -> 0 | K5: =RTD("rtdtrading.rtdserver",, "FRP0_F_0", "AJA") -> 0 | L5: =RTD("rtdtrading.rtdserver",, "FRP0_F_0", "VEN") -> 11/09/2026 | M5: =RTD("rtdtrading.rtdserver",, "FRP0_F_0", "101_RGM_AJUSTE_D0_DOL")
A6: WDOFUT | B6: =RTD("rtdtrading.rtdserver",, "WDOFUT_F_0", "DAT") -> 30/12/1899 | C6: =RTD("rtdtrading.rtdserver",, "WDOFUT_F_0", "HOR") -> 00:00:00 | D6: =RTD("rtdtrading.rtdserver",, "WDOFUT_F_0", "ULT") -> 0 | E6: =RTD("rtdtrading.rtdserver",, "WDOFUT_F_0", "ABE") -> 0 | F6: =RTD("rtdtrading.rtdserver",, "WDOFUT_F_0", "MAX") -> 0 | G6: =RTD("rtdtrading.rtdserver",, "WDOFUT_F_0", "MIN") -> 0 | H6: =RTD("rtdtrading.rtdserver",, "WDOFUT_F_0", "FEC") -> 0 | I6: =RTD("rtdtrading.rtdserver",, "WDOFUT_F_0", "VAR") -> 0 | J6: =RTD("rtdtrading.rtdserver",, "WDOFUT_F_0", "AJU") -> 0 | K6: =RTD("rtdtrading.rtdserver",, "WDOFUT_F_0", "AJA") -> 0 | L6: =RTD("rtdtrading.rtdserver",, "WDOFUT_F_0", "VEN") -> 11/09/2026 | M6: =RTD("rtdtrading.rtdserver",, "WDOFUT_F_0", "101_RGM_AJUSTE_D0_DOL")
